<?xml version="1.0" ?>
<!-- =================================================================================== -->
<!-- |    This document was autogenerated by xacro from /home/zhan/Projects/robot_grasp_project/code/ROBOT/src/my_robot_description/urdf/ur8_arm_robot/my_ur8_arm_robot.xacro | -->
<!-- |    EDITING THIS FILE BY HAND IS NOT RECOMMENDED                                 | -->
<!-- =================================================================================== -->
<robot name="ur8_arm_robot">
  <link name="world_link">
    <!-- mass=0 让 Gazebo 把 world_link 当作静态锚点，不受重力下落 -->
    <inertial>
      <origin rpy="0 0 0" xyz="0 0 0"/>
      <mass value="0.0"/>
      <inertia ixx="0.001" ixy="0" ixz="0" iyy="0.001" iyz="0" izz="0.001"/>
    </inertial>
  </link>
  <link name="base_link">
    <inertial>
      <origin rpy="0 0 0" xyz="1.5846968960167 6.11398890853487E-05 -0.775179775404272"/>
      <mass value="1907.41473384"/>
      <inertia ixx="3637.15037900" ixy="0" ixz="0" iyy="2785.35216803" iyz="0" izz="5500.0"/>
    </inertial>
    <visual>
      <origin rpy="0 0 0" xyz="0 0 0"/>
      <geometry>
        <mesh filename="meshes/base_link.STL"/>
      </geometry>
      <material name="">
        <color rgba="1 0 0.956862745098039 1"/>
      </material>
    </visual>
      <collision><origin xyz="2.0600 0.0000 -1.0675" rpy="0 0 0"/><geometry><cylinder radius="2.2660" length="2.7225"/></geometry></collision>
    
  </link>
  <joint name="base_joint" type="fixed">
    <origin rpy="0 0 0" xyz="0 0 2.30499999999997"/>
    <parent link="world_link"/>
    <child link="base_link"/>
    <axis xyz="0 0 0"/>
  </joint>
  <link name="link1">
    <inertial>
      <origin rpy="0 0 0" xyz="0.0603922336440408 0.0275464750533206 1.06605487618985"/>
      <mass value="551.54733752"/>
      <inertia ixx="145.63389370" ixy="2.277776496" ixz="-12.77374849" iyy="169.22568119" iyz="-8.88482954" izz="48.049666198"/>
    </inertial>
    <visual>
      <origin rpy="0 0 0" xyz="0 0 0"/>
      <geometry>
        <mesh filename="meshes/link1.STL"/>
      </geometry>
      <material name="">
        <color rgba="0.529411764705882 0.549019607843137 0.549019607843137 1"/>
      </material>
    </visual>
      <collision><origin xyz="0.0000 -0.0846 0.9980" rpy="0 0 0"/><geometry><cylinder radius="0.5835" length="1.7644"/></geometry></collision>
    
  </link>
  <joint name="joint1" type="prismatic">
    <origin rpy="1.5707963267949 0 1.5707963267949" xyz="0 0 0"/>
    <parent link="base_link"/>
    <child link="link1"/>
    <axis xyz="0 0 1"/>
    <limit effort="30000" lower="0" upper="0.9" velocity="0.3"/>
  </joint>
  <link name="link2">
    <inertial>
      <origin rpy="0 0 0" xyz="0.322167586538568 0.00077562500279192 0.0692507520912388"/>
      <mass value="222.45326799"/>
      <inertia ixx="19.20512831" ixy="0.00277484" ixz="0.38041803" iyy="17.70157815" iyz="0.03951501" izz="5.15823428"/>
    </inertial>
    <visual>
      <origin rpy="0 0 0" xyz="0 0 0"/>
      <geometry>
        <mesh filename="meshes/link2.STL"/>
      </geometry>
      <material name="">
        <color rgba="0.752941176470588 0.752941176470588 0.752941176470588 1"/>
      </material>
    </visual>
      <collision><origin xyz="0.3126 0.0000 0.0605" rpy="0 0 0"/><geometry><cylinder radius="0.5582" length="0.4521"/></geometry></collision>
    
  </link>
  <joint name="joint2" type="revolute">
    <origin rpy="3.14159265358979 1.5707963267949 0" xyz="0.194 -0.0645999999999746 1.303"/>
    <parent link="link1"/>
    <child link="link2"/>
    <axis xyz="0 0 1"/>
    <limit effort="25000" lower="0" upper="3.14" velocity="0.8"/>
  </joint>
  <link name="link3">
    <inertial>
      <origin rpy="0 0 0" xyz="0.229433951620328 0.000277653268500218 0.118891752311527"/>
      <mass value="127.25594144"/>
      <inertia ixx="7.09334003" ixy="0.00486341" ixz="0.16603774" iyy="6.455412365" iyz="0.00633604" izz="2.357779031"/>
    </inertial>
    <visual>
      <origin rpy="0 0 0" xyz="0 0 0"/>
      <geometry>
        <mesh filename="meshes/link3.STL"/>
      </geometry>
      <material name="">
        <color rgba="0.752941176470588 0.752941176470588 0.752941176470588 1"/>
      </material>
    </visual>
      <collision><origin xyz="0.1960 0.0000 0.1325" rpy="0 0 0"/><geometry><cylinder radius="0.4070" length="0.3355"/></geometry></collision>
    
  </link>
  <joint name="joint3" type="revolute">
    <origin rpy="0 0 3.14159265358979" xyz="0.609999999999998 0 0.219000000000001"/>
    <parent link="link2"/>
    <child link="link3"/>
    <axis xyz="0 0 1"/>
    <limit effort="22000" lower="-3.14" upper="0" velocity="0.9"/>
  </joint>
  <link name="link4">
    <inertial>
      <origin rpy="0 0 0" xyz="0.122732786756185 -0.0500949925882772 0.205443375402954"/>
      <mass value="187.87093244"/>
      <inertia ixx="10.50305026" ixy="-0.96658849" ixz="0.23910359" iyy="3.99084189" iyz="0.61890927" izz="9.23939967"/>
    </inertial>
    <visual>
      <origin rpy="0 0 0" xyz="0 0 0"/>
      <geometry>
        <mesh filename="meshes/link4.STL"/>
      </geometry>
      <material name="">
        <color rgba="0.752941176470588 0.752941176470588 0.752941176470588 1"/>
      </material>
    </visual>
      <collision><origin xyz="0.1922 -0.0187 0.2090" rpy="0 0 0"/><geometry><cylinder radius="0.4029" length="0.4598"/></geometry></collision>
    
  </link>
  <joint name="joint4" type="revolute">
    <origin rpy="-1.5707963267949 0 -1.5707963267949" xyz="0.512999999999999 0 0.129999999999999"/>
    <parent link="link3"/>
    <child link="link4"/>
    <axis xyz="0 0 -1"/>
    <limit effort="20000" lower="-0.1745" upper="0.1745" velocity="1"/>
  </joint>
  <link name="link5">
    <inertial>
      <origin rpy="0 0 0" xyz="0.411195858367017 6.97142193929468E-05 0.0703008048528007"/>
      <mass value="185.18127937"/>
      <inertia ixx="13.11370264" ixy="0.00969962" ixz="0.68649935" iyy="12.48257290" iyz="0.01337311" izz="3.355581956"/>
    </inertial>
    <visual>
      <origin rpy="0 0 0" xyz="0 0 0"/>
      <geometry>
        <mesh filename="meshes/link5.STL"/>
      </geometry>
      <material name="">
        <color rgba="0.752941176470588 0.752941176470588 0.752941176470588 1"/>
      </material>
    </visual>
      <collision><origin xyz="0.3377 0.0000 0.0850" rpy="0 0 0"/><geometry><cylinder radius="0.5387" length="0.4400"/></geometry></collision>
    
  </link>
  <joint name="joint5" type="revolute">
    <origin rpy="-1.5707963267949 1.5707963267949 0" xyz="0.375999999999997 -0.0399999999999946 0.235500000000004"/>
    <parent link="link4"/>
    <child link="link5"/>
    <axis xyz="0 0 1"/>
    <limit effort="15000" lower="-3.14" upper="0" velocity="1.2"/>
  </joint>
  <link name="link6">
    <inertial>
      <origin rpy="0 0 0" xyz="0.355421358371012 0.0089123076176113 0.0959898870594774"/>
      <mass value="125.17866784"/>
      <inertia ixx="10.63907105" ixy="0.04557751" ixz="-0.15646614" iyy="9.97353524" iyz="-0.2061528" izz="1.29188035"/>
    </inertial>
    <visual>
      <origin rpy="0 0 0" xyz="0 0 0"/>
      <geometry>
        <mesh filename="meshes/link6.STL"/>
      </geometry>
      <material name="">
        <color rgba="0.752941176470588 0.752941176470588 0.752941176470588 1"/>
      </material>
    </visual>
      <collision><origin xyz="0.3506 0.0012 0.0804" rpy="0 0 0"/><geometry><cylinder radius="0.5515" length="0.2430"/></geometry></collision>
    
  </link>
  <joint name="joint6" type="revolute">
    <origin rpy="0 0 -3.14159265358979" xyz="0.649999999999999 0 0.225000000000004"/>
    <parent link="link5"/>
    <child link="link6"/>
    <axis xyz="0 0 1"/>
    <limit effort="15000" lower="0" upper="3.14" velocity="1"/>
  </joint>
  <link name="link7">
    <inertial>
      <origin rpy="0 0 0" xyz="0.0596188962912736 9.76126392671639E-05 0.0878434419731533"/>
      <mass value="27.72436675"/>
      <inertia ixx="0.32518947" ixy="7.012e-06" ixz="0.01846554" iyy="0.26482831" iyz="2.2309e-05" izz="0.21490676"/>
    </inertial>
    <visual>
      <origin rpy="0 0 0" xyz="0 0 0"/>
      <geometry>
        <mesh filename="meshes/link7.STL"/>
      </geometry>
      <material name="">
        <color rgba="0.752941176470588 0.752941176470588 0.752941176470588 1"/>
      </material>
    </visual>
      <collision><origin xyz="0.0425 -0.0028 0.1050" rpy="0 0 0"/><geometry><cylinder radius="0.1716" length="0.2310"/></geometry></collision>
    
  </link>
  <joint name="joint7" type="revolute">
    <origin rpy="3.14159265358979 0 0" xyz="0.71000000000002 0 0.0719999999999967"/>
    <parent link="link6"/>
    <child link="link7"/>
    <axis xyz="0 0 1"/>
    <limit effort="12000" lower="-3.14" upper="3.14" velocity="1.3"/>
  </joint>
  <link name="link8">
    <inertial>
      <origin rpy="0 0 0" xyz="9.49166006902757E-09 -2.12063889226677E-08 0.0928335712615604"/>
      <mass value="57.61027620"/>
      <inertia ixx="1.34765816" ixy="0.03561661" ixz="-0.44869963" iyy="2.27166836" iyz="0.00167257" izz="1.80503759"/>
    </inertial>
    <visual>
      <origin rpy="0 0 0" xyz="0 0 0"/>
      <geometry>
        <mesh filename="meshes/link8.STL"/>
      </geometry>
      <material name="">
        <color rgba="0.341176470588235 0.83921568627451 0.411764705882353 1"/>
      </material>
    </visual>
      <collision><origin xyz="0.0000 0.0000 0.1626" rpy="0 0 0"/><geometry><cylinder radius="0.2640" length="0.3578"/></geometry></collision>
    
  </link>
  <joint name="joint8" type="revolute">
    <origin rpy="0 1.5707963267949 0" xyz="0.182499999999997 0 0.104999999999999"/>
    <parent link="link7"/>
    <child link="link8"/>
    <axis xyz="0 0 1"/>
    <limit effort="10000" lower="-3.14" upper="3.14" velocity="1"/>
  </joint>
  <link name="link_tool">
    <inertial>
      <origin rpy="0 0 0" xyz="0 0 0"/>
      <mass value="0.1"/>
      <inertia ixx="0.001" ixy="0" ixz="0" iyy="0.001" iyz="0" izz="0.001"/>
    </inertial>
  </link>
  <joint name="joint_tool" type="fixed">
    <origin rpy="0 0 0" xyz="0 0 0.460000000000001"/>
    <parent link="link8"/>
    <child link="link_tool"/>
    <axis xyz="0 0 0"/>
  </joint>
  <link name="link_grasp_base">
    <inertial>
      <origin rpy="0 0 0" xyz="0 0 0"/>
      <mass value="0.1"/>
      <inertia ixx="0.001" ixy="0" ixz="0" iyy="0.001" iyz="0" izz="0.001"/>
    </inertial>
  </link>
  <joint name="joint_grasp_base" type="fixed">
    <origin rpy="1.5707963267949 -1.5707963267949 0" xyz="0 0 0"/>
    <parent link="link_tool"/>
    <child link="link_grasp_base"/>
    <axis xyz="0 0 0"/>
  </joint>
  <link name="link_grasp_left">
    <inertial>
      <origin rpy="0 0 0" xyz="0.192574178667514 -0.0231365870139162 0.000631311328087969"/>
      <mass value="15.84360858"/>
      <inertia ixx="0.30757026" ixy="4.1898e-05" ixz="0.01111072" iyy="0.24191696" iyz="-1.5166e-05" izz="0.111258058"/>
    </inertial>
    <visual>
      <origin rpy="0 0 0" xyz="0 0 0"/>
      <geometry>
        <mesh filename="meshes/link_grasp_left.STL"/>
      </geometry>
      <material name="">
        <color rgba="0.529411764705882 0.549019607843137 0.549019607843137 1"/>
      </material>
    </visual>
      <collision><origin xyz="0.2260 -0.0161 0.0000" rpy="0 0 0"/><geometry><cylinder radius="0.3007" length="0.2310"/></geometry></collision>
      <collision><origin xyz="-0.1240 -0.1746 0.0000" rpy="0 0 0"/><geometry><cylinder radius="0.3007" length="0.2310"/></geometry></collision>
      <collision><origin xyz="-0.1746 0.0000 -0.1240" rpy="0 0 0"/><geometry><cylinder radius="0.1155" length="0.6013"/></geometry></collision>
    
  </link>
  <joint name="joint_grasp_left" type="revolute">
    <origin rpy="0 0 0" xyz="-0.35 -0.158500000000002 0"/>
    <parent link="link_grasp_base"/>
    <child link="link_grasp_left"/>
    <axis xyz="0 0 1"/>
    <limit effort="500" lower="-0.1745" upper="0.1745" velocity="0.5"/>
  </joint>
  <link name="link_grasp_right">
    <inertial>
      <origin rpy="0 0 0" xyz="0.192574178667513 0.0231365870139186 -0.000631311328087025"/>
      <mass value="15.84360858"/>
      <inertia ixx="0.30757026" ixy="4.1898e-05" ixz="0.01111072" iyy="0.24191696" iyz="-1.5166e-05" izz="0.111258058"/>
    </inertial>
    <visual>
      <origin rpy="0 0 0" xyz="0 0 0"/>
      <geometry>
        <mesh filename="meshes/link_grasp_right.STL"/>
      </geometry>
      <material name="">
        <color rgba="0.529411764705882 0.549019607843137 0.549019607843137 1"/>
      </material>
    </visual>
      <collision><origin xyz="0.2260 0.0161 0.0000" rpy="0 0 0"/><geometry><cylinder radius="0.3007" length="0.2310"/></geometry></collision>
    
  </link>
  <joint name="joint_grasp_right" type="revolute">
    <origin rpy="0 0 0" xyz="-0.350000000000001 0.158499999999998 0"/>
    <parent link="link_grasp_base"/>
    <child link="link_grasp_right"/>
    <axis xyz="0 0 1"/>
    <limit effort="500" lower="-0.1745" upper="0.1745" velocity="0.5"/>
  </joint>
  <link name="link_knife">
    <inertial>
      <origin rpy="0 0 0" xyz="0.0001046638970994 7.00958256394935E-05 -0.00777174761489619"/>
      <mass value="28.9246716834852"/>
      <inertia ixx="0.413269083135069" ixy="-2.60321422728687e-05" ixz="3.85004912773947e-06" iyy="0.413302041648517" iyz="9.20605717701595e-08" izz="0.497555385805286"/>
    </inertial>
    <visual>
      <origin rpy="0 0 0" xyz="0 0 0"/>
      <geometry>
        <mesh filename="meshes/link_knife.STL"/>
      </geometry>
      <material name="">
        <color rgba="0.792156862745098 0.819607843137255 0.933333333333333 1"/>
      </material>
    </visual>
    
  </link>
  <joint name="joint_knife" type="fixed">
    <origin rpy="0 0 0" xyz="3.68850000000001 -0.0370675931515342 1.28149999999999"/>
    <parent link="world_link"/>
    <child link="link_knife"/>
    <axis xyz="0 0 0"/>
  </joint>
  <!-- 防止 world_link 受重力下落（所有 Gazebo 模式通用） -->
  <gazebo reference="world_link">
    <gravity>false</gravity>
  </gazebo>
</robot>
